

Here are the remaining errors of CPython 2.5's test_itertools.  FWIW I
consider them all as obscure undocumented implementation details.


======================================================================
ERROR: test_islice (__main__.TestBasicOps)
----------------------------------------------------------------------
Traceback (most recent call last):
  File "test_itertools.py", line 285, in test_islice
    self.assertRaises(ValueError, islice, xrange(10), 'a')
  File "/home/arigo/pypysrc/lib-python/2.4.1/unittest.py", line 322, in failUnlessRaises
    return
  File "/home/arigo/pypysrc/lib-python/2.4.1/unittest.py", line 320, in failUnlessRaises
    callableObj(*args, **kwargs)
TypeError: expected integer, got str object

======================================================================
ERROR: test_tee (__main__.TestBasicOps)
----------------------------------------------------------------------
Traceback (most recent call last):
  File "itest25.py", line 376, in test_tee
    c = type(a)('def')
TypeError: default __new__ takes no parameters

======================================================================
ERROR: test_repeat (__main__.LengthTransparency)
----------------------------------------------------------------------
Traceback (most recent call last):
  File "itest25.py", line 690, in test_repeat
    from test.test_iterlen import len
ImportError: cannot import name 'len'

======================================================================
ERROR: test_keywords_in_subclass (__main__.SubclassWithKwargsTest)
----------------------------------------------------------------------
Traceback (most recent call last):
  File "itest25.py", line 760, in test_keywords_in_subclass
    class Subclass(cls):
TypeError: type 'repeat' is not an acceptable base class

======================================================================
FAIL: test_count (__main__.TestBasicOps)
----------------------------------------------------------------------
Traceback (most recent call last):
  File "itest25.py", line 59, in test_count
    self.assertEqual(repr(c), 'count(3)')
AssertionError: '<count object at 0x08fcdcac>' != 'count(3)'

======================================================================
FAIL: test_izip (__main__.TestBasicOps)
----------------------------------------------------------------------
Traceback (most recent call last):
  File "itest25.py", line 199, in test_izip
    self.assertEqual(min(ids), max(ids))
AssertionError: 149283404 != 150789644

======================================================================
FAIL: test_repeat (__main__.TestBasicOps)
----------------------------------------------------------------------
Traceback (most recent call last):
  File "itest25.py", line 214, in test_repeat
    self.assertEqual(repr(r), 'repeat((1+0j))')
AssertionError: '<repeat object at 0x09124a2c>' != 'repeat((1+0j))'

----------------------------------------------------------------------
